Workbook

Sheet README
B1: Excel Dashboard Project - Supermarket Sales
B2: Made by Prince (BCA) | Dataset: Supermarket Sales from Kaggle
B4: About the data
B5: I took the Supermarket Sales dataset from Kaggle. It has 1000 bills from 3 branches (Yangon, Mandalay, Naypyitaw) from 1 Jan to 30 Mar 2019.
B6: Each bill has product line, customer type, gender, payment method, time and a rating.
B7: What I wanted to find: which product lines, cities, payment types and timings bring the most sales.
B9: Tasks and where I did them
B10: Task | C10: Sheet | D10: What I used | E10: Time (min)
B11: 1. Dataset import (5%) | C11: Raw_Data, Lists | D11: CSV import, first check | E11: 15
B12: 2. Cleaning (10%) | C12: Clean_Data, Cleaning_Log | D12: Duplicates, blanks, date/time types | E12: 25
B13: 3. Pivot tables (15%) | C13: Pivot_Analysis | D13: SUMIFS / COUNTIFS summary tables | E13: 30
B14: 4. Advanced formulas (15%) | C14: Formulas, Clean_Data cols Q-V | D14: VLOOKUP, INDEX-MATCH, IF, nested IF | E14: 35
B15: 5. Visualization (20%) | C15: Dashboard, Pivot_Analysis | D15: Charts, colour scales, data bars | E15: 40
B16: 6. Interactive dashboard (25%) | C16: Dashboard | D16: Dropdown filters, KPI boxes, named ranges | E16: 45
B17: 7. Documentation (10%) | C17: README, Cleaning_Log | D17: Notes and naming | E17: 20
B19: Sheets
B20: Dashboard - main page. Change the 3 yellow boxes (city, product line, month) and everything updates.
B21: Pivot_Analysis - summary tables. Formulas - lookup and IF practice. Chart_Data - small tables behind the charts (don't edit).
B22: Clean_Data - cleaned data (table name tblSales). Raw_Data - original copy. Cleaning_Log - what I checked. Lists - dropdown lists and settings.
B24: How to use
B25: Go to Dashboard and pick from the yellow boxes. 'All' means no filter. The weekly chart does not use the month filter, so the full timeline always shows.
B26: Settings like what is a Large order or Excellent rating are in Lists (yellow cells). Change them and the columns update.
B27: I made named ranges (rngTotal, rngCity etc.) so new rows added below the table are counted automatically.
B28: For slicers: click inside Clean_Data, then Table Design > Insert Slicer. Same way for a PivotTable (Insert > PivotTable).
B30: Names and colours
B31: Sheet names use underscore. Named ranges start with rng, settings start with set, table is tblSales.
B32: Yellow cell with blue text = you can type/change. Teal = headings. Font is Arial everywhere.
... B38: My pivot tables are formula based, not the Excel PivotTable object. This way they stay connected to the dashboard.

Sheet Dashboard
B1: Supermarket Sales Dashboard
B3: ="Showing: "&B5&" | "&E5&" | "&I5&" (Jan to Mar 2019, "&TEXT(COUNTA(Clean_Data!A:A)-1,"#,##0")&" invoices in the file)" -> Showing: All | All | All (Jan to Mar 2019, 1,000 invoices in the file)
B4: BRANCH / CITY | E4: PRODUCT LINE | I4: MONTH | L4: Change the yellow boxes, everything below changes.
B5: All | E5: All | I5: All
B7: TOTAL SALES | D7: GROSS INCOME | F7: INVOICES | H7: AVG SALE / INVOICE | J7: AVG RATING (4-10) | L7: SHARE OF ALL SALES
B8: =SUMIFS(rngTotal,rngCity,Chart_Data!$C$4,rngProduct,Chart_Data!$C$5,rngMonth,Chart_Data!$C$6) -> 322966.75 | D8: =SUMIFS(rngGross,rngCity,Chart_Data!$C$4,rngProduct,Chart_Data!$C$5,rngMonth,Chart_Data!$C$6) -> 15379.369 | F8: =COUNTIFS(rngCity,Chart_Data!$C$4,rngProduct,Chart_Data!$C$5,rngMonth,Chart_Data!$C$6) -> 1000 | H8: =IFERROR(B8/F8,0) -> 322.96675 | J8: =IFERROR(AVERAGEIFS(rngRating,rngCity,Chart_Data!$C$4,rngProduct,Chart_Data!$C$5,rngMonth,Chart_Data!$C$6),0) -> 6.9727 | L8: =IFERROR(B8/SUM(rngTotal),0) -> 1
B10: Sales = Total column (includes 5% tax). Currency not given. Gross Income = tax in this data, see README.
H43: QUICK POINTS (as per filters)
H44: ="Top product line: "&INDEX(Chart_Data!B10:B15,MATCH(MAX(Chart_Data!C10:C15),Chart_Data!C10:C15,0)) -> Top product line: Food and beverages
H46: ="Weakest product line: "&INDEX(Chart_Data!B10:B15,MATCH(MIN(Chart_Data!C10:C15),Chart_Data!C10:C15,0)) -> Weakest product line: Health and beauty
H48: ="Best week: starting "&INDEX(Chart_Data!B19:B31,MATCH(MAX(Chart_Data!C19:C31),Chart_Data!C19:C31,0))&" ("&TEXT(MAX(Chart_Data!C19:C31),"#,##0")&")" -> Best week: starting 22 Jan (31,894)
H50: ="Top payment method: "&INDEX(Chart_Data!B36:B38,MATCH(MAX(Chart_Data!C36:C38),Chart_Data!C36:C38,0)) -> Top payment method: Cash
H52: ="Top city: "&INDEX(Chart_Data!B42:B44,MATCH(MAX(Chart_Data!C42:C44),Chart_Data!C42:C44,0)) -> Top city: Naypyitaw
H54: ="Busiest hour: "&INDEX(Chart_Data!B48:B58,MATCH(MAX(Chart_Data!C48:C58),Chart_Data!C48:C58,0))&" ("&TEXT(MAX(Chart_Data!C48:C58),"#,##0")&")" -> Busiest hour: 19:00 (39,700)
H56: For slicers see README.

Sheet Pivot_Analysis
B1: Pivot Analysis
B2: Summary tables made with SUMIFS / COUNTIFS / AVERAGEIFS.
B4: 1. Performance by Product Line
B5: Product Line | C5: Invoices | D5: Units | E5: Sales | F5: Gross Income | G5: Avg Sale | H5: Avg Rating | I5: % of Sales | J5: Rank
B6: Food and beverages | C6: =COUNTIFS(rngProduct,$B6) -> 174 | D6: =SUMIFS(rngQty,rngProduct,$B6) -> 952 | E6: =SUMIFS(rngTotal,rngProduct,$B6) -> 56144.844 | F6: =SUMIFS(rngGross,rngProduct,$B6) -> 2673.564 | G6: =IFERROR(E6/C6,0) -> 322.67152 | H6: =IFERROR(AVERAGEIFS(rngRating,rngProduct,$B6),0) -> 7.1132184 | I6: =IFERROR(E6/$E$12,0) -> 0.17384094 | J6: =RANK(E6,$E$6:$E$11) -> 1
B7: Sports and travel | C7: =COUNTIFS(rngProduct,$B7) -> 166 | D7: =SUMIFS(rngQty,rngProduct,$B7) -> 920 | E7: =SUMIFS(rngTotal,rngProduct,$B7) -> 55122.827 | F7: =SUMIFS(rngGross,rngProduct,$B7) -> 2624.8965 | G7: =IFERROR(E7/C7,0) -> 332.06522 | H7: =IFERROR(AVERAGEIFS(rngRating,rngProduct,$B7),0) -> 6.9162651 | I7: =IFERROR(E7/$E$12,0) -> 0.17067648 | J7: =RANK(E7,$E$6:$E$11) -> 2
B8: Electronic accessories | C8: =COUNTIFS(rngProduct,$B8) -> 170 | D8: =SUMIFS(rngQty,rngProduct,$B8) -> 971 | E8: =SUMIFS(rngTotal,rngProduct,$B8) -> 54337.531 | F8: =SUMIFS(rngGross,rngProduct,$B8) -> 2587.5015 | G8: =IFERROR(E8/C8,0) -> 319.63254 | H8: =IFERROR(AVERAGEIFS(rngRating,rngProduct,$B8),0) -> 6.9247059 | I8: =IFERROR(E8/$E$12,0) -> 0.16824497 | J8: =RANK(E8,$E$6:$E$11) -> 3
B9: Fashion accessories | C9: =COUNTIFS(rngProduct,$B9) -> 178 | D9: =SUMIFS(rngQty,rngProduct,$B9) -> 902 | E9: =SUMIFS(rngTotal,rngProduct,$B9) -> 54305.895 | F9: =SUMIFS(rngGross,rngProduct,$B9) -> 2585.995 | G9: =IFERROR(E9/C9,0) -> 305.0893 | H9: =IFERROR(AVERAGEIFS(rngRating,rngProduct,$B9),0) -> 7.0292135 | I9: =IFERROR(E9/$E$12,0) -> 0.16814702 | J9: =RANK(E9,$E$6:$E$11) -> 4
B10: Home and lifestyle | C10: =COUNTIFS(rngProduct,$B10) -> 160 | D10: =SUMIFS(rngQty,rngProduct,$B10) -> 911 | E10: =SUMIFS(rngTotal,rngProduct,$B10) -> 53861.913 | F10: =SUMIFS(rngGross,rngProduct,$B10) -> 2564.853 | G10: =IFERROR(E10/C10,0) -> 336.63696 | H10: =IFERROR(AVERAGEIFS(rngRating,rngProduct,$B10),0) -> 6.8375 | I10: =IFERROR(E10/$E$12,0) -> 0.16677232 | J10: =RANK(E10,$E$6:$E$11) -> 5
B11: Health and beauty | C11: =COUNTIFS(rngProduct,$B11) -> 152 | D11: =SUMIFS(rngQty,rngProduct,$B11) -> 854 | E11: =SUMIFS(rngTotal,rngProduct,$B11) -> 49193.739 | F11: =SUMIFS(rngGross,rngProduct,$B11) -> 2342.559 | G11: =IFERROR(E11/C11,0) -> 323.64302 | H11: =IFERROR(AVERAGEIFS(rngRating,rngProduct,$B11),0) -> 7.0032895 | I11: =IFERROR(E11/$E$12,0) -> 0.15231828 | J11: =RANK(E11,$E$6:$E$11) -> 6
B12: Total | C12: =SUM(C6:C11) -> 1000 | D12: =SUM(D6:D11) -> 5510 | E12: =SUM(E6:E11) -> 322966.75 | F12: =SUM(F6:F11) -> 15379.369 | G12: =IFERROR(E12/C12,0) -> 322.96675 | H12: =AVERAGE(rngRating) -> 6.9727 | I12: =SUM(I6:I11) -> 1
B15: 2. Sales Matrix: City x Product Line
B16: City | C16: Food and beverages | D16: Sports and travel | E16: Electronic accessories | F16: Fashion accessories | G16: Home and lifestyle | H16: Health and beauty | I16: Total
B17: Yangon | C17: =SUMIFS(rngTotal,rngCity,$B17,rngProduct,C$16) -> 17163.101 | D17: =SUMIFS(rngTotal,rngCity,$B17,rngProduct,D$16) -> 19372.699 | E17: =SUMIFS(rngTotal,rngCity,$B17,rngProduct,E$16) -> 18317.113 | F17: =SUMIFS(rngTotal,rngCity,$B17,rngProduct,F$16) -> 16332.508 | G17: =SUMIFS(rngTotal,rngCity,$B17,rngProduct,G$16) -> 22417.196 | H17: =SUMIFS(rngTotal,rngCity,$B17,rngProduct,H$16) -> 12597.753 | I17: =SUM(C17:H17) -> 106200.37
B18: Mandalay | C18: =SUMIFS(rngTotal,rngCity,$B18,rngProduct,C$16) -> 15214.888 | D18: =SUMIFS(rngTotal,rngCity,$B18,rngProduct,D$16) -> 19988.199 | E18: =SUMIFS(rngTotal,rngCity,$B18,rngProduct,E$16) -> 17051.444 | F18: =SUMIFS(rngTotal,rngCity,$B18,rngProduct,F$16) -> 16413.317 | G18: =SUMIFS(rngTotal,rngCity,$B18,rngProduct,G$16) -> 17549.164 | H18: =SUMIFS(rngTotal,rngCity,$B18,rngProduct,H$16) -> 19980.66 | I18: =SUM(C18:H18) -> 106197.67
B19: Naypyitaw | C19: =SUMIFS(rngTotal,rngCity,$B19,rngProduct,C$16) -> 23766.855 | D19: =SUMIFS(rngTotal,rngCity,$B19,rngProduct,D$16) -> 15761.928 | E19: =SUMIFS(rngTotal,rngCity,$B19,rngProduct,E$16) -> 18968.975 | F19: =SUMIFS(rngTotal,rngCity,$B19,rngProduct,F$16) -> 21560.07 | G19: =SUMIFS(rngTotal,rngCity,$B19,rngProduct,G$16) -> 13895.553 | H19: =SUMIFS(rngTotal,rngCity,$B19,rngProduct,H$16) -> 16615.326 | I19: =SUM(C19:H19) -> 110568.71
B20: Total | C20: =SUM(C17:C19) -> 56144.844 | D20: =SUM(D17:D19) -> 55122.827 | E20: =SUM(E17:E19) -> 54337.531 | F20: =SUM(F17:F19) -> 54305.895 | G20: =SUM(G17:G19) -> 53861.913 | H20: =SUM(H17:H19) -> 49193.739 | I20: =SUM(I17:I19) -> 322966.75
B23: 3. Monthly Trend
B24: Month | C24: Invoices | D24: Sales | E24: Avg Sale | F24: MoM Growth
B25: Jan | C25: =COUNTIFS(rngMonth,$B25) -> 352 | D25: =SUMIFS(rngTotal,rngMonth,$B25) -> 116291.87 | E25: =IFERROR(D25/C25,0) -> 330.37462 | F25: n/a
B26: Feb | C26: =COUNTIFS(rngMonth,$B26) -> 303 | D26: =SUMIFS(rngTotal,rngMonth,$B26) -> 97219.374 | E26: =IFERROR(D26/C26,0) -> 320.85602 | F26: =IFERROR(D26/D25-1,0) -> -0.1640054
B27: Mar | C27: =COUNTIFS(rngMonth,$B27) -> 345 | D27: =SUMIFS(rngTotal,rngMonth,$B27) -> 109455.51 | E27: =IFERROR(D27/C27,0) -> 317.26234 | F27: =IFERROR(D27/D26-1,0) -> 0.12586106
B30: 4. Payment Method
B31: Payment | C31: Invoices | D31: Sales | E31: % of Sales
B32: Cash | C32: =COUNTIFS(rngPayment,$B32) -> 344 | D32: =SUMIFS(rngTotal,rngPayment,$B32) -> 112206.57 | E32: =IFERROR(D32/$D$35,0) -> 0.34742453
B33: Ewallet | C33: =COUNTIFS(rngPayment,$B33) -> 345 | D33: =SUMIFS(rngTotal,rngPayment,$B33) -> 109993.11 | E33: =IFERROR(D33/$D$35,0) -> 0.34057099
B34: Credit card | C34: =COUNTIFS(rngPayment,$B34) -> 311 | D34: =SUMIFS(rngTotal,rngPayment,$B34) -> 100767.07 | E34: =IFERROR(D34/$D$35,0) -> 0.31200448
B35: Total | C35: =SUM(C32:C34) -> 1000 | D35: =SUM(D32:D34) -> 322966.75 | E35: =SUM(E32:E34) -> 1
B38: 5. Sales: Customer Type x Gender
B39: Customer Type | C39: Female | D39: Male | E39: Total
B40: Member | C40: =SUMIFS(rngTotal,rngCust,$B40,rngGender,C$39) -> 88146.943 | D40: =SUMIFS(rngTotal,rngCust,$B40,rngGender,D$39) -> 76076.5 | E40: =SUM(C40:D40) -> 164223.44
B41: Normal | C41: =SUMIFS(rngTotal,rngCust,$B41,rngGender,C$39) -> 79735.981 | D41: =SUMIFS(rngTotal,rngCust,$B41,rngGender,D$39) -> 79007.323 | E41: =SUM(C41:D41) -> 158743.3
B42: Total | C42: =SUM(C40:C41) -> 167882.92 | D42: =SUM(D40:D41) -> 155083.82 | E42: =SUM(E40:E41) -> 322966.75
B45: 6. Time of Day
B46: Time Slot | C46: Invoices | D46: Sales | E46: % of Sales
B47: Morning | C47: =COUNTIFS(rngSlot,$B47) -> 191 | D47: =SUMIFS(rngTotal,rngSlot,$B47) -> 61798.81 | E47: =IFERROR(D47/SUM($D$47:$D$49),0) -> 0.19134728
B48: Afternoon | C48: =COUNTIFS(rngSlot,$B48) -> 454 | D48: =SUMIFS(rngTotal,rngSlot,$B48) -> 148023.34 | E48: =IFERROR(D48/SUM($D$47:$D$49),0) -> 0.45832378
B49: Evening | C49: =COUNTIFS(rngSlot,$B49) -> 355 | D49: =SUMIFS(rngTotal,rngSlot,$B49) -> 113144.6 | E49: =IFERROR(D49/SUM($D$47:$D$49),0) -> 0.35032894
B52: 7. Sales by Hour of Day
B53: Hour | C53: Invoices | D53: Sales
...

Sheet Formulas
B1: Formulas Practice
B2: Yellow cells = type here. Everything else is a formula. Short note on the right of each part.
B4: A. Invoice Lookup: VLOOKUP vs INDEX-MATCH
B5: Enter Invoice ID: | C5: 750-67-8428 | D5: <- type any Invoice ID from Clean_Data
B6: Field | C6: VLOOKUP | D6: INDEX-MATCH | E6: Same?
B7: City | C7: =IFERROR(VLOOKUP($C$5,Clean_Data!$A:$P,3,FALSE()),"Not found") -> Yangon | D7: =IFERROR(INDEX(Clean_Data!$C:$C,MATCH($C$5,Clean_Data!$A:$A,0)),"Not found") -> Yangon | E7: =IF(C7=D7,"Match","Check") -> Match | F7: VLOOKUP needs the ID in the first column and a column number (3, 6, 8...). INDEX-MATCH picks the column directly so it does not break if a column is added. IFERROR shows Not found instead of an error.
B8: Product Line | C8: =IFERROR(VLOOKUP($C$5,Clean_Data!$A:$P,6,FALSE()),"Not found") -> Health and beauty | D8: =IFERROR(INDEX(Clean_Data!$F:$F,MATCH($C$5,Clean_Data!$A:$A,0)),"Not found") -> Health and beauty | E8: =IF(C8=D8,"Match","Check") -> Match
B9: Quantity | C9: =IFERROR(VLOOKUP($C$5,Clean_Data!$A:$P,8,FALSE()),"Not found") -> 7 | D9: =IFERROR(INDEX(Clean_Data!$H:$H,MATCH($C$5,Clean_Data!$A:$A,0)),"Not found") -> 7 | E9: =IF(C9=D9,"Match","Check") -> Match
B10: Total | C10: =IFERROR(VLOOKUP($C$5,Clean_Data!$A:$P,10,FALSE()),"Not found") -> 548.9715 | D10: =IFERROR(INDEX(Clean_Data!$J:$J,MATCH($C$5,Clean_Data!$A:$A,0)),"Not found") -> 548.9715 | E10: =IF(C10=D10,"Match","Check") -> Match
B11: Rating | C11: =IFERROR(VLOOKUP($C$5,Clean_Data!$A:$P,16,FALSE()),"Not found") -> 9.1 | D11: =IFERROR(INDEX(Clean_Data!$P:$P,MATCH($C$5,Clean_Data!$A:$A,0)),"Not found") -> 9.1 | E11: =IF(C11=D11,"Match","Check") -> Match
B14: B. Left Lookup (INDEX-MATCH can look left, VLOOKUP cannot)
B15: Pick a city: | C15: Mandalay | F15: Branch code is on the left of City in the Lists table. VLOOKUP cannot look left, INDEX-MATCH can.
B16: Branch code: | C16: =IFERROR(INDEX(Lists!$A$2:$A$4,MATCH($C$15,Lists!$B$2:$B$4,0)),"Not found") -> B
B19: C. Two-way Lookup (INDEX + MATCH + MATCH)
B20: City: | C20: Yangon | F20: First MATCH finds the row (city), second MATCH finds the column (product line), INDEX gives the value where they meet in the Pivot_Analysis table.
B21: Product line: | C21: Food and beverages
B22: Sales: | C22: =IFERROR(INDEX(Pivot_Analysis!$C$17:$H$19,MATCH($C$20,Pivot_Analysis!$B$17:$B$19,0),MATCH($C$21,Pivot_Analysis!$C$16:$H$16,0)),"Not found") -> 17163.101
B25: D. Nested IF + AND/OR: Product Line Scorecard
B26: Product Line | C26: Sales | D26: Avg of Lines | E26: Sales / Avg | F26: Performance | G26: Action
B27: =Pivot_Analysis!B6 -> Food and beverages | C27: =Pivot_Analysis!E6 -> 56144.844 | D27: =AVERAGE(Pivot_Analysis!$E$6:$E$11) -> 53827.791 | E27: =IFERROR(C27/D27,0) -> 1.0430457 | F27: =IF(E27>=1+setPerfBand,"Above average",IF(E27>=1-setPerfBand,"On par","Below average")) -> On par | G27: =IF(AND(F27="Above average",Pivot_Analysis!H6>=Pivot_Analysis!$H$12),"Star: push",IF(OR(F27="Below average",Pivot_Analysis!H6<Pivot_Analysis!$H$12-0.2),"Review","Maintain")) -> Maintain
B28: =Pivot_Analysis!B7 -> Sports and travel | C28: =Pivot_Analysis!E7 -> 55122.827 | D28: =AVERAGE(Pivot_Analysis!$E$6:$E$11) -> 53827.791 | E28: =IFERROR(C28/D28,0) -> 1.0240589 | F28: =IF(E28>=1+setPerfBand,"Above average",IF(E28>=1-setPerfBand,"On par","Below average")) -> On par | G28: =IF(AND(F28="Above average",Pivot_Analysis!H7>=Pivot_Analysis!$H$12),"Star: push",IF(OR(F28="Below average",Pivot_Analysis!H7<Pivot_Analysis!$H$12-0.2),"Review","Maintain")) -> Maintain
B29: =Pivot_Analysis!B8 -> Electronic accessories | C29: =Pivot_Analysis!E8 -> 54337.531 | D29: =AVERAGE(Pivot_Analysis!$E$6:$E$11) -> 53827.791 | E29: =IFERROR(C29/D29,0) -> 1.0094698 | F29: =IF(E29>=1+setPerfBand,"Above average",IF(E29>=1-setPerfBand,"On par","Below average")) -> On par | G29: =IF(AND(F29="Above average",Pivot_Analysis!H8>=Pivot_Analysis!$H$12),"Star: push",IF(OR(F29="Below average",Pivot_Analysis!H8<Pivot_Analysis!$H$12-0.2),"Review","Maintain")) -> Maintain
B30: =Pivot_Analysis!B9 -> Fashion accessories | C30: =Pivot_Analysis!E9 -> 54305.895 | D30: =AVERAGE(Pivot_Analysis!$E$6:$E$11) -> 53827.791 | E30: =IFERROR(C30/D30,0) -> 1.0088821 | F30: =IF(E30>=1+setPerfBand,"Above average",IF(E30>=1-setPerfBand,"On par","Below average")) -> On par | G30: =IF(AND(F30="Above average",Pivot_Analysis!H9>=Pivot_Analysis!$H$12),"Star: push",IF(OR(F30="Below average",Pivot_Analysis!H9<Pivot_Analysis!$H$12-0.2),"Review","Maintain")) -> Maintain
B31: =Pivot_Analysis!B10 -> Home and lifestyle | C31: =Pivot_Analysis!E10 -> 53861.913 | D31: =AVERAGE(Pivot_Analysis!$E$6:$E$11) -> 53827.791 | E31: =IFERROR(C31/D31,0) -> 1.0006339 | F31: =IF(E31>=1+setPerfBand,"Above average",IF(E31>=1-setPerfBand,"On par","Below average")) -> On par | G31: =IF(AND(F31="Above average",Pivot_Analysis!H10>=Pivot_Analysis!$H$12),"Star: push",IF(OR(F31="Below average",Pivot_Analysis!H10<Pivot_Analysis!$H$12-0.2),"Review","Maintain")) -> Maintain
B32: =Pivot_Analysis!B11 -> Health and beauty | C32: =Pivot_Analysis!E11 -> 49193.739 | D32: =AVERAGE(Pivot_Analysis!$E$6:$E$11) -> 53827.791 | E32: =IFERROR(C32/D32,0) -> 0.91390967 | F32: =IF(E32>=1+setPerfBand,"Above average",IF(E32>=1-setPerfBand,"On par","Below average")) -> Below average | G32: =IF(AND(F32="Above average",Pivot_Analysis!H11>=Pivot_Analysis!$H$12),"Star: push",IF(OR(F32="Below average",Pivot_Analysis!H11<Pivot_Analysis!$H$12-0.2),"Review","Maintain")) -> Review
B33: Performance = nested IF, compares each line with the average of all 6 lines (+/-5%, set in Lists). Action = AND/OR with rating: Star = sales above average AND rating not below overall, Review = sales below average OR rating 0.2 lower than overall.
B37: E. Key points (written by formulas)
B38: ="Top product line: "&INDEX(Pivot_Analysis!B6:B11,MATCH(MAX(Pivot_Analysis!E6:E11),Pivot_Analysis!E6:E11,0))&" ("&TEXT(MAX(Pivot_Analysis!E6:E11),"#,##0")&" in sales, "&TEXT(MAX(Pivot_Analysis!I6:I11),"0.0%")&" of total)" -> Top product line: Food and beverages (56,145 in sales, 17.4% of total)
B39: ="Weakest product line: "&INDEX(Pivot_Analysis!B6:B11,MATCH(MIN(Pivot_Analysis!E6:E11),Pivot_Analysis!E6:E11,0))&" ("&TEXT(MIN(Pivot_Analysis!E6:E11),"#,##0")&")" -> Weakest product line: Health and beauty (49,194)
B40: ="Top city: "&INDEX(Pivot_Analysis!B17:B19,MATCH(MAX(Pivot_Analysis!I17:I19),Pivot_Analysis!I17:I19,0))&" ("&TEXT(MAX(Pivot_Analysis!I17:I19),"#,##0")&")" -> Top city: Naypyitaw (110,569)
B41: ="Best month: "&INDEX(Pivot_Analysis!B25:B27,MATCH(MAX(Pivot_Analysis!D25:D27),Pivot_Analysis!D25:D27,0))&" ("&TEXT(MAX(Pivot_Analysis!D25:D27),"#,##0")&")" -> Best month: Jan (116,292)
B42: ="Most used payment: "&INDEX(Pivot_Analysis!B32:B34,MATCH(MAX(Pivot_Analysis!C32:C34),Pivot_Analysis!C32:C34,0))&" ("&MAX(Pivot_Analysis!C32:C34)&" invoices)" -> Most used payment: Ewallet (345 invoices)
B43: ="Peak hour: "&INDEX(Pivot_Analysis!B54:B64,MATCH(MAX(Pivot_Analysis!D54:D64),Pivot_Analysis!D54:D64,0))&":00 ("&TEXT(MAX(Pivot_Analysis!D54:D64),"#,##0")&" in sales)" -> Peak hour: 19:00 (39,700 in sales)
B44: ="Members vs Normal: "&TEXT(Pivot_Analysis!E40/Pivot_Analysis!E42,"0.0%")&" of sales come from Members" -> Members vs Normal: 50.8% of sales come from Members

Sheet Chart_Data
B1: Chart Data
B2: These small tables feed the Dashboard charts. Please do not type here.
B4: Branch / City criterion | C4: =IF(Dashboard!$B$5="All","*",Dashboard!$B$5) -> * | D4: "*" means All. Product chart ignores product filter, weekly chart ignores month filter.
B5: Product line criterion | C5: =IF(Dashboard!$E$5="All","*",Dashboard!$E$5) -> *
B6: Month criterion | C6: =IF(Dashboard!$I$5="All","*",Dashboard!$I$5) -> *
B8: Sales by Product Line (City + Month filters)
B9: Product Line | C9: Sales
B10: Food and beverages | C10: =SUMIFS(rngTotal,rngCity,$C$4,rngProduct,B10,rngMonth,$C$6) -> 56144.844
B11: Sports and travel | C11: =SUMIFS(rngTotal,rngCity,$C$4,rngProduct,B11,rngMonth,$C$6) -> 55122.827
B12: Electronic accessories | C12: =SUMIFS(rngTotal,rngCity,$C$4,rngProduct,B12,rngMonth,$C$6) -> 54337.531
B13: Fashion accessories | C13: =SUMIFS(rngTotal,rngCity,$C$4,rngProduct,B13,rngMonth,$C$6) -> 54305.895
B14: Home and lifestyle | C14: =SUMIFS(rngTotal,rngCity,$C$4,rngProduct,B14,rngMonth,$C$6) -> 53861.913
B15: Health and beauty | C15: =SUMIFS(rngTotal,rngCity,$C$4,rngProduct,B15,rngMonth,$C$6) -> 49193.739
B17: Weekly Trend (City + Product filters)
B18: Week starting | C18: Sales | D18: Week No
B19: =TEXT(setMinDate+(D19-1)*7,"d mmm") -> 1 Jan | C19: =SUMIFS(rngTotal,rngCity,$C$4,rngProduct,$C$5,rngWeek,D19) -> 20377.633 | D19: 1
B20: =TEXT(setMinDate+(D20-1)*7,"d mmm") -> 8 Jan | C20: =SUMIFS(rngTotal,rngCity,$C$4,rngProduct,$C$5,rngWeek,D20) -> 25593.571 | D20: 2
B21: =TEXT(setMinDate+(D21-1)*7,"d mmm") -> 15 Jan | C21: =SUMIFS(rngTotal,rngCity,$C$4,rngProduct,$C$5,rngWeek,D21) -> 27118.843 | D21: 3
B22: =TEXT(setMinDate+(D22-1)*7,"d mmm") -> 22 Jan | C22: =SUMIFS(rngTotal,rngCity,$C$4,rngProduct,$C$5,rngWeek,D22) -> 31894.496 | D22: 4
B23: =TEXT(setMinDate+(D23-1)*7,"d mmm") -> 29 Jan | C23: =SUMIFS(rngTotal,rngCity,$C$4,rngProduct,$C$5,rngWeek,D23) -> 25800.232 | D23: 5
B24: =TEXT(setMinDate+(D24-1)*7,"d mmm") -> 5 Feb | C24: =SUMIFS(rngTotal,rngCity,$C$4,rngProduct,$C$5,rngWeek,D24) -> 29204.49 | D24: 6
B25: =TEXT(setMinDate+(D25-1)*7,"d mmm") -> 12 Feb | C25: =SUMIFS(rngTotal,rngCity,$C$4,rngProduct,$C$5,rngWeek,D25) -> 22517.47 | D25: 7
B26: =TEXT(setMinDate+(D26-1)*7,"d mmm") -> 19 Feb | C26: =SUMIFS(rngTotal,rngCity,$C$4,rngProduct,$C$5,rngWeek,D26) -> 20639.871 | D26: 8
B27: =TEXT(setMinDate+(D27-1)*7,"d mmm") -> 26 Feb | C27: =SUMIFS(rngTotal,rngCity,$C$4,rngProduct,$C$5,rngWeek,D27) -> 28306.918 | D27: 9
B28: =TEXT(setMinDate+(D28-1)*7,"d mmm") -> 5 Mar | C28: =SUMIFS(rngTotal,rngCity,$C$4,rngProduct,$C$5,rngWeek,D28) -> 27485.65 | D28: 10
B29: =TEXT(setMinDate+(D29-1)*7,"d mmm") -> 12 Mar | C29: =SUMIFS(rngTotal,rngCity,$C$4,rngProduct,$C$5,rngWeek,D29) -> 22321.803 | D29: 11
B30: =TEXT(setMinDate+(D30-1)*7,"d mmm") -> 19 Mar | C30: =SUMIFS(rngTotal,rngCity,$C$4,rngProduct,$C$5,rngWeek,D30) -> 26100.732 | D30: 12
B31: =TEXT(setMinDate+(D31-1)*7,"d mmm") -> 26 Mar | C31: =SUMIFS(rngTotal,rngCity,$C$4,rngProduct,$C$5,rngWeek,D31) -> 15605.037 | D31: 13
B34: Sales by Payment (all filters)
B35: Payment | C35: Sales
B36: Cash | C36: =SUMIFS(rngTotal,rngCity,$C$4,rngProduct,$C$5,rngMonth,$C$6,rngPayment,B36) -> 112206.57
B37: Ewallet | C37: =SUMIFS(rngTotal,rngCity,$C$4,rngProduct,$C$5,rngMonth,$C$6,rngPayment,B37) -> 109993.11
B38: Credit card | C38: =SUMIFS(rngTotal,rngCity,$C$4,rngProduct,$C$5,rngMonth,$C$6,rngPayment,B38) -> 100767.07
B40: Sales by City (Product + Month filters)
B41: City | C41: Sales
B42: Yangon | C42: =SUMIFS(rngTotal,rngCity,B42,rngProduct,$C$5,rngMonth,$C$6) -> 106200.37
B43: Mandalay | C43: =SUMIFS(rngTotal,rngCity,B43,rngProduct,$C$5,rngMonth,$C$6) -> 106197.67
B44: Naypyitaw | C44: =SUMIFS(rngTotal,rngCity,B44,rngProduct,$C$5,rngMonth,$C$6) -> 110568.71
B46: Sales by Hour (all filters)
B47: Hour | C47: Sales | D47: Hour no.
...

Sheet Clean_Data
A1: Invoice ID | B1: Branch | C1: City | D1: Customer Type | E1: Gender | F1: Product Line | G1: Unit Price | H1: Quantity | I1: Tax 5% | J1: Total | K1: Date | L1: Time | M1: Payment | N1: COGS | O1: Gross Income | P1: Rating | Q1: Month | R1: Week No | S1: Hour | T1: Time Slot | U1: Order Size | V1: Rating Band | X1: Columns Q to V are formulas. Limits (Large order etc.) are on the Lists sheet.
A2: 750-67-8428 | B2: A | C2: Yangon | D2: Member | E2: Female | F2: Health and beauty | G2: 74.69 | H2: 7 | I2: 26.1415 | J2: 548.9715 | K2: 43470 | L2: 0.54722222 | M2: Ewallet | N2: 522.83 | O2: 26.1415 | P2: 9.1 | Q2: =CHOOSE(MONTH(K2),"Jan","Feb","Mar","Apr","May","Jun","Jul","Aug","Sep","Oct","Nov","Dec") -> Jan | R2: =INT((K2-setMinDate)/7)+1 -> 1 | S2: =HOUR(L2) -> 13 | T2: =IF(S2<setMorningEnd,"Morning",IF(S2<setAfternoonEnd,"Afternoon","Evening")) -> Afternoon | U2: =IF(J2>=setLarge,"Large",IF(J2>=setMedium,"Medium","Small")) -> Medium | V2: =IF(P2>=setExc,"Excellent",IF(P2>=setGood,"Good",IF(P2>=setAvg,"Average","Poor"))) -> Excellent
A3: 226-31-3081 | B3: C | C3: Naypyitaw | D3: Normal | E3: Female | F3: Electronic accessories | G3: 15.28 | H3: 5 | I3: 3.82 | J3: 80.22 | K3: 43532 | L3: 0.43680556 | M3: Cash | N3: 76.4 | O3: 3.82 | P3: 9.6 | Q3: =CHOOSE(MONTH(K3),"Jan","Feb","Mar","Apr","May","Jun","Jul","Aug","Sep","Oct","Nov","Dec") -> Mar | R3: =INT((K3-setMinDate)/7)+1 -> 10 | S3: =HOUR(L3) -> 10 | T3: =IF(S3<setMorningEnd,"Morning",IF(S3<setAfternoonEnd,"Afternoon","Evening")) -> Morning | U3: =IF(J3>=setLarge,"Large",IF(J3>=setMedium,"Medium","Small")) -> Small | V3: =IF(P3>=setExc,"Excellent",IF(P3>=setGood,"Good",IF(P3>=setAvg,"Average","Poor"))) -> Excellent
A4: 631-41-3108 | B4: A | C4: Yangon | D4: Normal | E4: Male | F4: Home and lifestyle | G4: 46.33 | H4: 7 | I4: 16.2155 | J4: 340.5255 | K4: 43527 | L4: 0.55763889 | M4: Credit card | N4: 324.31 | O4: 16.2155 | P4: 7.4 | Q4: =CHOOSE(MONTH(K4),"Jan","Feb","Mar","Apr","May","Jun","Jul","Aug","Sep","Oct","Nov","Dec") -> Mar | R4: =INT((K4-setMinDate)/7)+1 -> 9 | S4: =HOUR(L4) -> 13 | T4: =IF(S4<setMorningEnd,"Morning",IF(S4<setAfternoonEnd,"Afternoon","Evening")) -> Afternoon | U4: =IF(J4>=setLarge,"Large",IF(J4>=setMedium,"Medium","Small")) -> Medium | V4: =IF(P4>=setExc,"Excellent",IF(P4>=setGood,"Good",IF(P4>=setAvg,"Average","Poor"))) -> Good
A5: 123-19-1176 | B5: A | C5: Yangon | D5: Member | E5: Male | F5: Health and beauty | G5: 58.22 | H5: 8 | I5: 23.288 | J5: 489.048 | K5: 43492 | L5: 0.85625 | M5: Ewallet | N5: 465.76 | O5: 23.288 | P5: 8.4 | Q5: =CHOOSE(MONTH(K5),"Jan","Feb","Mar","Apr","May","Jun","Jul","Aug","Sep","Oct","Nov","Dec") -> Jan | R5: =INT((K5-setMinDate)/7)+1 -> 4 | S5: =HOUR(L5) -> 20 | T5: =IF(S5<setMorningEnd,"Morning",IF(S5<setAfternoonEnd,"Afternoon","Evening")) -> Evening | U5: =IF(J5>=setLarge,"Large",IF(J5>=setMedium,"Medium","Small")) -> Medium | V5: =IF(P5>=setExc,"Excellent",IF(P5>=setGood,"Good",IF(P5>=setAvg,"Average","Poor"))) -> Good
A6: 373-73-7910 | B6: A | C6: Yangon | D6: Normal | E6: Male | F6: Sports and travel | G6: 86.31 | H6: 7 | I6: 30.2085 | J6: 634.3785 | K6: 43504 | L6: 0.44236111 | M6: Ewallet | N6: 604.17 | O6: 30.2085 | P6: 5.3 | Q6: =CHOOSE(MONTH(K6),"Jan","Feb","Mar","Apr","May","Jun","Jul","Aug","Sep","Oct","Nov","Dec") -> Feb | R6: =INT((K6-setMinDate)/7)+1 -> 6 | S6: =HOUR(L6) -> 10 | T6: =IF(S6<setMorningEnd,"Morning",IF(S6<setAfternoonEnd,"Afternoon","Evening")) -> Morning | U6: =IF(J6>=setLarge,"Large",IF(J6>=setMedium,"Medium","Small")) -> Large | V6: =IF(P6>=setExc,"Excellent",IF(P6>=setGood,"Good",IF(P6>=setAvg,"Average","Poor"))) -> Average
A7: 699-14-3026 | B7: C | C7: Naypyitaw | D7: Normal | E7: Male | F7: Electronic accessories | G7: 85.39 | H7: 7 | I7: 29.8865 | J7: 627.6165 | K7: 43549 | L7: 0.77083333 | M7: Ewallet | N7: 597.73 | O7: 29.8865 | P7: 4.1 | Q7: =CHOOSE(MONTH(K7),"Jan","Feb","Mar","Apr","May","Jun","Jul","Aug","Sep","Oct","Nov","Dec") -> Mar | R7: =INT((K7-setMinDate)/7)+1 -> 12 | S7: =HOUR(L7) -> 18 | T7: =IF(S7<setMorningEnd,"Morning",IF(S7<setAfternoonEnd,"Afternoon","Evening")) -> Evening | U7: =IF(J7>=setLarge,"Large",IF(J7>=setMedium,"Medium","Small")) -> Large | V7: =IF(P7>=setExc,"Excellent",IF(P7>=setGood,"Good",IF(P7>=setAvg,"Average","Poor"))) -> Poor
A8: 355-53-5943 | B8: A | C8: Yangon | D8: Member | E8: Female | F8: Electronic accessories | G8: 68.84 | H8: 6 | I8: 20.652 | J8: 433.692 | K8: 43521 | L8: 0.60833333 | M8: Ewallet | N8: 413.04 | O8: 20.652 | P8: 5.8 | Q8: =CHOOSE(MONTH(K8),"Jan","Feb","Mar","Apr","May","Jun","Jul","Aug","Sep","Oct","Nov","Dec") -> Feb | R8: =INT((K8-setMinDate)/7)+1 -> 8 | S8: =HOUR(L8) -> 14 | T8: =IF(S8<setMorningEnd,"Morning",IF(S8<setAfternoonEnd,"Afternoon","Evening")) -> Afternoon | U8: =IF(J8>=setLarge,"Large",IF(J8>=setMedium,"Medium","Small")) -> Medium | V8: =IF(P8>=setExc,"Excellent",IF(P8>=setGood,"Good",IF(P8>=setAvg,"Average","Poor"))) -> Average
A9: 315-22-5665 | B9: C | C9: Naypyitaw | D9: Normal | E9: Female | F9: Home and lifestyle | G9: 73.56 | H9: 10 | I9: 36.78 | J9: 772.38 | K9: 43520 | L9: 0.48472222 | M9: Ewallet | N9: 735.6 | O9: 36.78 | P9: 8 | Q9: =CHOOSE(MONTH(K9),"Jan","Feb","Mar","Apr","May","Jun","Jul","Aug","Sep","Oct","Nov","Dec") -> Feb | R9: =INT((K9-setMinDate)/7)+1 -> 8 | S9: =HOUR(L9) -> 11 | T9: =IF(S9<setMorningEnd,"Morning",IF(S9<setAfternoonEnd,"Afternoon","Evening")) -> Morning | U9: =IF(J9>=setLarge,"Large",IF(J9>=setMedium,"Medium","Small")) -> Large | V9: =IF(P9>=setExc,"Excellent",IF(P9>=setGood,"Good",IF(P9>=setAvg,"Average","Poor"))) -> Good
A10: 665-32-9167 | B10: A | C10: Yangon | D10: Member | E10: Female | F10: Health and beauty | G10: 36.26 | H10: 2 | I10: 3.626 | J10: 76.146 | K10: 43475 | L10: 0.71875 | M10: Credit card | N10: 72.52 | O10: 3.626 | P10: 7.2 | Q10: =CHOOSE(MONTH(K10),"Jan","Feb","Mar","Apr","May","Jun","Jul","Aug","Sep","Oct","Nov","Dec") -> Jan | R10: =INT((K10-setMinDate)/7)+1 -> 2 | S10: =HOUR(L10) -> 17 | T10: =IF(S10<setMorningEnd,"Morning",IF(S10<setAfternoonEnd,"Afternoon","Evening")) -> Evening | U10: =IF(J10>=setLarge,"Large",IF(J10>=setMedium,"Medium","Small")) -> Small | V10: =IF(P10>=setExc,"Excellent",IF(P10>=setGood,"Good",IF(P10>=setAvg,"Average","Poor"))) -> Good
A11: 692-92-5582 | B11: B | C11: Mandalay | D11: Member | E11: Female | F11: Food and beverages | G11: 54.84 | H11: 3 | I11: 8.226 | J11: 172.746 | K11: 43516 | L11: 0.56041667 | M11: Credit card | N11: 164.52 | O11: 8.226 | P11: 5.9 | Q11: =CHOOSE(MONTH(K11),"Jan","Feb","Mar","Apr","May","Jun","Jul","Aug","Sep","Oct","Nov","Dec") -> Feb | R11: =INT((K11-setMinDate)/7)+1 -> 8 | S11: =HOUR(L11) -> 13 | T11: =IF(S11<setMorningEnd,"Morning",IF(S11<setAfternoonEnd,"Afternoon","Evening")) -> Afternoon | U11: =IF(J11>=setLarge,"Large",IF(J11>=setMedium,"Medium","Small")) -> Small | V11: =IF(P11>=setExc,"Excellent",IF(P11>=setGood,"Good",IF(P11>=setAvg,"Average","Poor"))) -> Average
A12: 351-62-0822 | B12: B | C12: Mandalay | D12: Member | E12: Female | F12: Fashion accessories | G12: 14.48 | H12: 4 | I12: 2.896 | J12: 60.816 | K12: 43502 | L12: 0.75486111 | M12: Ewallet | N12: 57.92 | O12: 2.896 | P12: 4.5 | Q12: =CHOOSE(MONTH(K12),"Jan","Feb","Mar","Apr","May","Jun","Jul","Aug","Sep","Oct","Nov","Dec") -> Feb | R12: =INT((K12-setMinDate)/7)+1 -> 6 | S12: =HOUR(L12) -> 18 | T12: =IF(S12<setMorningEnd,"Morning",IF(S12<setAfternoonEnd,"Afternoon","Evening")) -> Evening | U12: =IF(J12>=setLarge,"Large",IF(J12>=setMedium,"Medium","Small")) -> Small | V12: =IF(P12>=setExc,"Excellent",IF(P12>=setGood,"Good",IF(P12>=setAvg,"Average","Poor"))) -> Poor
A13: 529-56-3974 | B13: B | C13: Mandalay | D13: Member | E13: Male | F13: Electronic accessories | G13: 25.51 | H13: 4 | I13: 5.102 | J13: 107.142 | K13: 43533 | L13: 0.71041667 | M13: Cash | N13: 102.04 | O13: 5.102 | P13: 6.8 | Q13: =CHOOSE(MONTH(K13),"Jan","Feb","Mar","Apr","May","Jun","Jul","Aug","Sep","Oct","Nov","Dec") -> Mar | R13: =INT((K13-setMinDate)/7)+1 -> 10 | S13: =HOUR(L13) -> 17 | T13: =IF(S13<setMorningEnd,"Morning",IF(S13<setAfternoonEnd,"Afternoon","Evening")) -> Evening | U13: =IF(J13>=setLarge,"Large",IF(J13>=setMedium,"Medium","Small")) -> Small | V13: =IF(P13>=setExc,"Excellent",IF(P13>=setGood,"Good",IF(P13>=setAvg,"Average","Poor"))) -> Average
... A1001: 849-09-3807 | B1001: A | C1001: Yangon | D1001: Member | E1001: Female | F1001: Fashion accessories | G1001: 88.34 | H1001: 7 | I1001: 30.919 | J1001: 649.299 | K1001: 43514 | L1001: 0.56111111 | M1001: Cash | N1001: 618.38 | O1001: 30.919 | P1001: 6.6 | Q1001: =CHOOSE(MONTH(K1001),"Jan","Feb","Mar","Apr","May","Jun","Jul","Aug","Sep","Oct","Nov","Dec") -> Feb | R1001: =INT((K1001-setMinDate)/7)+1 -> 7 | S1001: =HOUR(L1001) -> 13 | T1001: =IF(S1001<setMorningEnd,"Morning",IF(S1001<setAfternoonEnd,"Afternoon","Evening")) -> Afternoon | U1001: =IF(J1001>=setLarge,"Large",IF(J1001>=setMedium,"Medium","Small")) -> Large | V1001: =IF(P1001>=setExc,"Excellent",IF(P1001>=setGood,"Good",IF(P1001>=setAvg,"Average","Poor"))) -> Average

Sheet Raw_Data
A1: Invoice ID | B1: Branch | C1: City | D1: Customer type | E1: Gender | F1: Product line | G1: Unit price | H1: Quantity | I1: Tax 5% | J1: Total | K1: Date | L1: Time | M1: Payment | N1: Cost of goods sold | O1: Gross margin percentage | P1: Gross income | Q1: Customer stratification rating | S1: Original CSV copy, not edited (dates are still text here).
A2: 750-67-8428 | B2: A | C2: Yangon | D2: Member | E2: Female | F2: Health and beauty | G2: 74.69 | H2: 7 | I2: 26.1415 | J2: 548.9715 | K2: 1/5/2019 | L2: 13:08 | M2: Ewallet | N2: 522.83 | O2: 4.7619048 | P2: 26.1415 | Q2: 9.1
A3: 226-31-3081 | B3: C | C3: Naypyitaw | D3: Normal | E3: Female | F3: Electronic accessories | G3: 15.28 | H3: 5 | I3: 3.82 | J3: 80.22 | K3: 3/8/2019 | L3: 10:29 | M3: Cash | N3: 76.4 | O3: 4.7619048 | P3: 3.82 | Q3: 9.6
A4: 631-41-3108 | B4: A | C4: Yangon | D4: Normal | E4: Male | F4: Home and lifestyle | G4: 46.33 | H4: 7 | I4: 16.2155 | J4: 340.5255 | K4: 3/3/2019 | L4: 13:23 | M4: Credit card | N4: 324.31 | O4: 4.7619048 | P4: 16.2155 | Q4: 7.4
A5: 123-19-1176 | B5: A | C5: Yangon | D5: Member | E5: Male | F5: Health and beauty | G5: 58.22 | H5: 8 | I5: 23.288 | J5: 489.048 | K5: 1/27/2019 | L5: 20:33 | M5: Ewallet | N5: 465.76 | O5: 4.7619048 | P5: 23.288 | Q5: 8.4
A6: 373-73-7910 | B6: A | C6: Yangon | D6: Normal | E6: Male | F6: Sports and travel | G6: 86.31 | H6: 7 | I6: 30.2085 | J6: 634.3785 | K6: 2/8/2019 | L6: 10:37 | M6: Ewallet | N6: 604.17 | O6: 4.7619048 | P6: 30.2085 | Q6: 5.3
A7: 699-14-3026 | B7: C | C7: Naypyitaw | D7: Normal | E7: Male | F7: Electronic accessories | G7: 85.39 | H7: 7 | I7: 29.8865 | J7: 627.6165 | K7: 3/25/2019 | L7: 18:30 | M7: Ewallet | N7: 597.73 | O7: 4.7619048 | P7: 29.8865 | Q7: 4.1
A8: 355-53-5943 | B8: A | C8: Yangon | D8: Member | E8: Female | F8: Electronic accessories | G8: 68.84 | H8: 6 | I8: 20.652 | J8: 433.692 | K8: 2/25/2019 | L8: 14:36 | M8: Ewallet | N8: 413.04 | O8: 4.7619048 | P8: 20.652 | Q8: 5.8
A9: 315-22-5665 | B9: C | C9: Naypyitaw | D9: Normal | E9: Female | F9: Home and lifestyle | G9: 73.56 | H9: 10 | I9: 36.78 | J9: 772.38 | K9: 2/24/2019 | L9: 11:38 | M9: Ewallet | N9: 735.6 | O9: 4.7619048 | P9: 36.78 | Q9: 8
A10: 665-32-9167 | B10: A | C10: Yangon | D10: Member | E10: Female | F10: Health and beauty | G10: 36.26 | H10: 2 | I10: 3.626 | J10: 76.146 | K10: 1/10/2019 | L10: 17:15 | M10: Credit card | N10: 72.52 | O10: 4.7619048 | P10: 3.626 | Q10: 7.2
A11: 692-92-5582 | B11: B | C11: Mandalay | D11: Member | E11: Female | F11: Food and beverages | G11: 54.84 | H11: 3 | I11: 8.226 | J11: 172.746 | K11: 2/20/2019 | L11: 13:27 | M11: Credit card | N11: 164.52 | O11: 4.7619048 | P11: 8.226 | Q11: 5.9
A12: 351-62-0822 | B12: B | C12: Mandalay | D12: Member | E12: Female | F12: Fashion accessories | G12: 14.48 | H12: 4 | I12: 2.896 | J12: 60.816 | K12: 2/6/2019 | L12: 18:07 | M12: Ewallet | N12: 57.92 | O12: 4.7619048 | P12: 2.896 | Q12: 4.5
A13: 529-56-3974 | B13: B | C13: Mandalay | D13: Member | E13: Male | F13: Electronic accessories | G13: 25.51 | H13: 4 | I13: 5.102 | J13: 107.142 | K13: 3/9/2019 | L13: 17:03 | M13: Cash | N13: 102.04 | O13: 4.7619048 | P13: 5.102 | Q13: 6.8
... A1001: 849-09-3807 | B1001: A | C1001: Yangon | D1001: Member | E1001: Female | F1001: Fashion accessories | G1001: 88.34 | H1001: 7 | I1001: 30.919 | J1001: 649.299 | K1001: 2/18/2019 | L1001: 13:28 | M1001: Cash | N1001: 618.38 | O1001: 4.7619048 | P1001: 30.919 | Q1001: 6.6

Sheet Cleaning_Log
B1: Data Cleaning Log
B2: All checks are formulas, so they recalculate by themselves.
B4: # | C4: Check | D4: Result | E4: Action taken
B5: 1 | C5: Rows imported (Raw_Data) | D5: =COUNTA(Raw_Data!A:A)-1 -> 1000 | E5: Dataset loaded from CSV with 17 columns.
B6: 2 | C6: Duplicate Invoice IDs | D6: =SUMPRODUCT(--(COUNTIF(Raw_Data!A2:A1001,Raw_Data!A2:A1001)>1)) -> 0 | E6: No duplicates found, so nothing removed.
B7: 3 | C7: Blank cells in data | D7: =COUNTBLANK(Raw_Data!A2:Q1001) -> 0 | E7: No blanks found.
B8: 4 | C8: Dates stored as text (before cleaning) | D8: =SUMPRODUCT(--ISTEXT(Raw_Data!K2:K1001)) -> 1000 | E8: Converted from text m/d/yyyy to real Excel dates.
B9: 5 | C9: Times stored as text (before cleaning) | D9: =SUMPRODUCT(--ISTEXT(Raw_Data!L2:L1001)) -> 1000 | E9: Converted from text hh:mm to real Excel times.
B10: 6 | C10: Dates stored as text (after cleaning) | D10: =SUMPRODUCT(--ISTEXT(Clean_Data!K2:K1001)) -> 0 | E10: Should be 0.
B11: 7 | C11: Rows where Total <> Unit price x Qty x 1.05 | D11: =SUMPRODUCT(--(ABS(Clean_Data!G2:G1001*Clean_Data!H2:H1001*1.05-Clean_Data!J2:J1001)>0.01)) -> 0 | E11: 0 means Total matches price x quantity + 5% tax.
B12: 8 | C12: Ratings outside 1-10 | D12: =COUNTIF(Clean_Data!P2:P1001,"<1")+COUNTIF(Clean_Data!P2:P1001,">10") -> 0 | E12: 0 means all ratings are between 1 and 10.
B13: 9 | C13: Rows in Clean_Data | D13: =COUNTA(Clean_Data!A:A)-1 -> 1000 | E13: Should equal rows imported.
B15: Other steps
B16: 1. Removed 'Gross margin percentage' from Clean_Data because it is 4.76 in every row (still there in Raw_Data).
B17: 2. Changed headings to Title Case and renamed the long rating column to just Rating.
B18: 3. Added columns Q to V with formulas: Month, Week No, Hour, Time Slot, Order Size, Rating Band.

Sheet Lists
A1: Branch Code | B1: City | D1: Product Line | F1: City Filter | G1: Product Filter | H1: Month Filter | K1: Setting | L1: Value | M1: Note
A2: A | B2: Yangon | D2: Food and beverages | F2: All | G2: All | H2: All | K2: Earliest sale date | L2: =MIN(rngDate) -> 43466 | M2: Formula - start of week numbering
A3: B | B3: Mandalay | D3: Sports and travel | F3: Yangon | G3: Food and beverages | H3: Jan | K3: Large order: Total >= | L3: 600 | M3: Assumption (analyst choice). 75th percentile of Total is about 471
A4: C | B4: Naypyitaw | D4: Electronic accessories | F4: Mandalay | G4: Sports and travel | H4: Feb | K4: Medium order: Total >= | L4: 250 | M4: Assumption. Median of Total is about 254
D5: Fashion accessories | F5: Naypyitaw | G5: Electronic accessories | H5: Mar | K5: Morning ends (hour <) | L5: 12 | M5: Assumption
D6: Home and lifestyle | G6: Fashion accessories | K6: Afternoon ends (hour <) | L6: 17 | M6: Assumption; evening = 17:00 onward
D7: Health and beauty | G7: Home and lifestyle | K7: Rating Excellent >= | L7: 9 | M7: Assumption (ratings run 4.0 to 10.0)
G8: Health and beauty | K8: Rating Good >= | L8: 7 | M8: Assumption
K9: Rating Average >= | L9: 5 | M9: Assumption; below this = Poor
A10: Lists are used for dropdowns and lookups. Yellow cells are settings you can change. | K10: Performance band (+/-) | L10: 0.05 | M10: Assumption: within +/-5% of the average product line = On par
